File: CuSO4_5H2O_Ref_1C_min_052119.txt
CLOSED
Version	0.4
Run	717
Instrument	2950 TGA       V5.4A
Module	TGA 1000 øC
Sample	CuSO4*5H2O standard slow
Size	8.07900	mg
Method
Operator	AE
Comment	CuSO4*5H2O standard at 1C/min for calibration
Xcomment	Pan: Platinum           Gas1: Nitrogen  20          Gas2: Nitrogen  30
Text
Kcell	1.00000
TempCal	2	pts	24.15	22.00,	374.82	354.00
Thresholds	0.050	0.0000
Controls	Gas 1  Event Off  Sampling 2.0 sec/pt
Nsig	3
Sig1	Time (min)
Sig2	Temperature (øC)
Sig3	Weight (mg)
Date	21-May-19
Time	17:52
File	C:\TA\Data\TGA\Angela\Cannabinoids\CuSO4_5H2O_Ref_1C_min_052119.001
OrgFile	C:\TA\Data\TGA\Angela\Cannabinoids\CuSO4_5H2O_Ref_1C_min_052119.001
0.0000000 26.67344 8.078762
0.2661666 27.33830 8.076782
0.5343334 27.79138 8.075806
0.8010000 28.08570 8.075093
1.067666 28.27563 8.074226
1.334334 28.38975 8.073325
1.601000 28.44875 8.072390
1.867833 28.52685 8.072134
2.134167 28.70288 8.071770
2.401000 28.93470 8.071309
2.667666 29.18101 8.070522
2.934334 29.43637 8.069988
3.201166 29.70138 8.068987
3.467666 29.96596 8.068070
3.734334 30.23304 8.067014
4.000834 30.49750 8.066298
4.267500 30.76815 8.065976
4.534167 31.03444 8.065660
4.801000 31.30160 8.065118
5.067833 31.56924 8.064245
5.334334 31.83545 8.063324
5.601000 32.10563 8.062619
5.867832 32.36596 8.061706
6.134332 32.63148 8.060822
6.401000 32.89762 8.060260
6.667500 33.16450 8.059692
6.939334 33.43860 8.058906
7.206168 33.70540 8.058237
7.476000 33.97351 8.057238
7.745332 34.24502 8.056161
8.014500 34.51156 8.055151
8.282666 34.78090 8.053912
8.549334 35.04806 8.052460
8.816168 35.31729 8.051281
9.082666 35.58026 8.050156
9.349334 35.85110 8.048440
9.616168 36.11630 8.047112
9.882668 36.38532 8.045852
10.14933 36.64698 8.044544
10.41617 36.91464 8.043306
10.68267 37.18042 8.042054
10.94934 37.44428 8.040845
11.21617 37.71556 8.039360
11.48600 37.98760 8.037094
11.75600 38.25932 8.035300
12.02450 38.51974 8.032822
12.29266 38.79416 8.029721
12.55934 39.06181 8.025903
12.82600 39.32870 8.020282
13.09250 39.59306 8.013738
13.35933 39.86139 8.007028
13.62583 40.12765 7.999640
13.89266 40.39270 7.992974
14.15934 40.66064 7.985009
14.42616 40.92791 7.977624
14.69266 41.19131 7.968732
14.95950 41.45717 7.959042
15.22617 41.72482 7.949540
15.49516 41.99288 7.939249
15.76617 42.26211 7.928081
16.03450 42.53415 7.917024
16.30266 42.80463 7.904835
16.57100 43.07450 7.891462
16.83767 43.33984 7.877184
17.10434 43.60650 7.863056
17.37100 43.86938 7.849170
17.63750 44.13774 7.834390
17.90450 44.40313 7.819056
18.17117 44.67309 7.803881
18.43784 44.93768 7.787995
18.70434 45.20252 7.772006
18.97100 45.47056 7.755811
19.23767 45.73650 7.738862
19.50434 46.00393 7.721756
19.77434 46.27696 7.703568
20.04184 46.54337 7.685676
20.31117 46.81004 7.667507
20.58100 47.08066 7.648034
20.84934 47.34993 7.628910
21.11934 47.61873 7.609600
21.38766 47.88299 7.589541
21.65434 48.14984 7.569646
21.92117 48.42066 7.549188
22.18766 48.68172 7.528738
22.45434 48.94740 7.508214
22.72100 49.21972 7.486807
22.98783 49.49199 7.465384
23.25450 49.76031 7.443891
23.52116 50.02689 7.422336
23.78750 50.28428 7.400754
24.05417 50.55304 7.379145
24.32117 50.81739 7.357595
24.58867 51.07944 7.335749
24.85766 51.35196 7.314245
25.12600 51.62574 7.293220
25.39266 51.89262 7.272153
25.65934 52.15797 7.251812
25.92600 52.41484 7.231378
26.19266 52.68618 7.211738
26.45950 52.95768 7.192202
26.72617 53.23349 7.173456
26.99284 53.50240 7.155381
27.25933 53.76135 7.137925
27.52600 54.02184 7.121170
27.79266 54.28316 7.104575
28.05933 54.55066 7.089232
28.32766 54.80157 7.074522
28.59617 55.08335 7.060416
28.86583 55.35818 7.046944
29.13516 55.62040 7.034756
29.40600 55.89536 7.023126
29.67450 56.17164 7.012803
29.94266 56.43422 7.003161
30.21433 56.70468 6.994056
30.48266 56.94965 6.985778
30.75100 57.16378 6.977999
31.01766 57.42211 6.971282
31.28434 57.69572 6.964969
31.55117 57.97422 6.958886
31.81784 58.26162 6.953134
32.08450 58.54465 6.948012
32.35100 58.82131 6.943016
32.61767 59.09911 6.938264
32.88434 59.36988 6.934292
33.15100 59.63896 6.929942
33.41783 59.90768 6.926272
33.68433 60.17274 6.922886
33.95100 60.44433 6.919818
34.22117 60.71442 6.917075
34.48950 60.98418 6.914632
34.75950 61.25740 6.912450
35.02850 61.52510 6.910560
35.29933 61.79316 6.908824
35.56766 62.06309 6.907451
35.83600 62.33212 6.905976
36.10784 62.60440 6.904624
36.37683 62.87028 6.903818
36.64767 63.14420 6.903497
36.91600 63.40166 6.902331
37.18433 63.68100 6.901569
37.45600 63.94337 6.900482
37.72516 64.20960 6.900032
37.99267 64.47216 6.899161
38.25917 64.75342 6.898670
38.52600 65.02394 6.897920
38.79266 65.29050 6.897005
39.05917 65.55421 6.896314
39.32617 65.80782 6.895500
39.59284 66.08212 6.894850
39.85950 66.34929 6.894212
40.12617 66.62139 6.893819
40.39284 66.88179 6.893156
40.65933 67.13581 6.892453
40.92600 67.39816 6.891689
41.19433 67.65876 6.890736
41.46600 67.92447 6.890272
41.73283 68.19148 6.889141
42.00266 68.46842 6.888250
42.27367 68.74990 6.887621
42.54283 69.01218 6.886865
42.81084 69.27110 6.886168
43.07784 69.53262 6.885401
43.34433 69.79890 6.884534
43.61100 70.06772 6.883619
43.87766 70.34514 6.882504
44.14433 70.61912 6.881646
44.41100 70.89502 6.880393
44.67766 71.16003 6.879054
44.94433 71.42016 6.877802
45.21100 71.69116 6.876549
45.47783 71.95550 6.875078
45.74600 72.22534 6.873818
46.01600 72.49421 6.872164
46.28450 72.76907 6.870868
46.55450 73.04410 6.869131
46.82350 73.30749 6.867364
47.09266 73.57722 6.865996
47.36434 73.84894 6.863900
47.63266 74.11988 6.862288
47.90266 74.38626 6.860062
48.17367 74.64740 6.858062
48.44117 74.91620 6.856112
48.71117 75.19443 6.853949
48.97934 75.46474 6.851656
49.24600 75.73510 6.849450
49.51266 76.00080 6.846976
49.77934 76.26641 6.844831
50.04600 76.53550 6.842119
50.31283 76.79768 6.839706
50.57916 77.05371 6.836701
50.84583 77.32122 6.833852
51.11266 77.59986 6.831269
51.37934 77.86297 6.828068
51.64600 78.12344 6.824880
51.91266 78.39268 6.821137
52.17934 78.66320 6.817870
52.44934 78.92813 6.814194
52.71866 79.19951 6.810562
52.98784 79.47405 6.806686
53.25950 79.73704 6.802626
53.52783 80.00718 6.798804
53.79783 80.28043 6.794394
54.06700 80.55074 6.789970
54.33584 80.81778 6.785106
54.60266 81.07486 6.780500
54.86934 81.33874 6.775295
55.13600 81.60852 6.770200
55.40266 81.87626 6.764956
55.66934 82.14306 6.759571
55.93600 82.40828 6.754114
56.20266 82.67452 6.748681
56.46950 82.94324 6.743400
56.73600 83.22012 6.737821
57.00283 83.48831 6.731926
57.26934 83.74676 6.726016
57.53600 84.00860 6.720114
57.80616 84.28368 6.714090
58.07250 84.54459 6.708305
58.33933 84.81574 6.702272
58.60600 85.07745 6.695881
58.87283 85.34842 6.689482
59.13950 85.62265 6.682799
59.40616 85.89392 6.675996
59.67250 86.15331 6.669210
59.93916 86.41920 6.662171
60.20600 86.68500 6.654694
60.47266 86.93863 6.646744
60.73916 87.21174 6.637634
61.00750 87.48634 6.626313
61.27617 87.75665 6.608632
61.54617 88.01362 6.578491
61.81533 88.28549 6.532162
62.08433 88.55176 6.472559
62.35600 88.82032 6.399113
62.62434 89.08749 6.320084
62.89450 89.37020 6.237976
63.16416 89.64657 6.157160
63.43266 89.91736 6.084926
63.69934 90.18466 6.025232
63.96600 90.45597 5.978558
64.23266 90.72839 5.944121
64.49950 90.99619 5.918711
64.76600 91.25360 5.899116
65.03266 91.51764 5.883944
65.29932 91.77711 5.871961
65.56616 92.04195 5.862481
65.83282 92.30811 5.855020
66.09934 92.57019 5.848940
66.36600 92.84009 5.844166
66.63266 93.10731 5.840026
66.90266 93.37899 5.837278
67.17116 93.64899 5.834840
67.43932 93.91614 5.832714
67.70600 94.18731 5.831345
67.97266 94.45829 5.829792
68.23932 94.72232 5.828560
68.50600 94.98816 5.827656
68.77266 95.25384 5.826990
69.03932 95.51649 5.826216
69.30584 95.78559 5.825380
69.57266 96.05278 5.824715
69.83950 96.31944 5.823826
70.10616 96.58586 5.823184
70.37266 96.85160 5.822922
70.64116 97.12244 5.822460
70.90932 97.39114 5.821716
71.17600 97.65702 5.821166
71.44282 97.92484 5.820821
71.70934 98.19141 5.820179
71.97600 98.45661 5.820099
72.24250 98.72241 5.819503
72.50932 98.98559 5.818950
72.77600 99.25398 5.818537
73.04282 99.52045 5.818246
73.30932 99.78465 5.817840
73.57616 100.0527 5.817377
73.84266 100.3223 5.816851
74.11100 100.5913 5.816567
74.37782 100.8578 5.816279
74.64450 101.1260 5.815868
74.91100 101.3921 5.815320
75.17782 101.6590 5.814882
75.44450 101.9269 5.814630
75.71100 102.1918 5.814687
75.97784 102.4572 5.814171
76.24450 102.7242 5.813622
76.51100 102.9895 5.813234
76.77766 103.2585 5.812930
77.04450 103.5258 5.812926
77.31366 103.7964 5.812678
77.58100 104.0627 5.812325
77.84782 104.3276 5.812135
78.11416 104.5946 5.811701
78.38100 104.8610 5.811248
78.64766 105.1272 5.810810
78.91450 105.3942 5.810290
79.18100 105.6599 5.810230
79.44782 105.9256 5.810250
79.71416 106.1911 5.809812
79.98100 106.4594 5.809565
80.24782 106.7263 5.809309
80.51684 106.9945 5.809065
80.78432 107.2623 5.808756
81.05450 107.5342 5.808407
81.32434 107.8030 5.808186
81.59266 108.0737 5.807895
81.86266 108.3441 5.807445
82.13282 108.6146 5.807033
82.40100 108.8830 5.806842
82.66934 109.1505 5.806428
82.93916 109.4199 5.805962
83.20850 109.6879 5.805708
83.47750 109.9572 5.805471
83.74432 110.2224 5.804944
84.01082 110.4885 5.804770
84.27766 110.7571 5.804578
84.54450 111.0232 5.804276
84.81100 111.2902 5.804038
85.07782 111.5560 5.803814
85.34432 111.8238 5.803515
85.61100 112.0912 5.803306
85.87782 112.3586 5.803171
86.14434 112.6247 5.803027
86.41101 112.8879 5.802589
86.67766 113.1542 5.802492
86.94782 113.4247 5.802158
87.21601 113.6922 5.801860
87.48266 113.9594 5.801328
87.74950 114.2279 5.801109
88.01582 114.4956 5.800703
88.28266 114.7626 5.800424
88.54932 115.0269 5.799965
88.81618 115.2932 5.799488
89.08282 115.5616 5.799576
89.34950 115.8282 5.799120
89.61600 116.0937 5.798762
89.88266 116.3607 5.798500
90.15266 116.6312 5.798264
90.42118 116.8993 5.798058
90.69118 117.1709 5.797856
90.96016 117.4386 5.797611
91.23116 117.7096 5.797295
91.49950 117.9798 5.797116
91.76782 118.2474 5.796778
92.03750 118.5169 5.796430
92.30766 118.7805 5.796022
92.57600 119.0515 5.795825
92.84766 119.3215 5.795386
93.11600 119.5904 5.795380
93.38600 119.8626 5.795018
93.65616 120.1354 5.794546
93.92600 120.4042 5.794101
94.19766 120.6763 5.793757
94.46450 120.9437 5.793620
94.73434 121.2115 5.793508
95.00450 121.4802 5.792974
95.27432 121.7507 5.792486
95.54282 122.0178 5.792199
95.81100 122.2880 5.792062
96.07766 122.5536 5.791960
96.34449 122.8211 5.791810
96.61100 123.0886 5.791495
96.87782 123.3532 5.791052
97.14434 123.6199 5.790666
97.41101 123.8869 5.790146
97.67750 124.1555 5.789895
97.94434 124.4200 5.789516
98.21082 124.6869 5.789313
98.47766 124.9551 5.789078
98.74450 125.2220 5.788848
99.01100 125.4878 5.788589
99.28266 125.7594 5.788435
99.55016 126.0275 5.788240
99.81949 126.2966 5.788057
100.0910 126.5682 5.787654
100.3577 126.8355 5.787363
100.6277 127.1033 5.787018
100.8970 127.3729 5.786656
101.1660 127.6432 5.786479
101.4327 127.9099 5.786197
101.6995 128.1765 5.785984
101.9660 128.4424 5.785584
102.2327 128.7106 5.785270
102.4993 128.9763 5.785034
102.7662 129.2410 5.784685
103.0327 129.5060 5.784270
103.2993 129.7754 5.783887
103.5660 130.0416 5.783611
103.8328 130.3098 5.783418
104.0993 130.5765 5.783064
104.3660 130.8439 5.782612
104.6362 131.1138 5.782302
104.9042 131.3812 5.781967
105.1743 131.6515 5.781680
105.4435 131.9211 5.781446
105.7128 132.1908 5.781184
105.9827 132.4587 5.780654
106.2510 132.7291 5.780372
106.5227 133.0010 5.780160
106.7912 133.2683 5.779800
107.0593 133.5344 5.779641
107.3260 133.7985 5.779230
107.5928 134.0658 5.778986
107.8593 134.3347 5.778639
108.1260 134.6022 5.778324
108.3928 134.8702 5.778116
108.6595 135.1409 5.777943
108.9260 135.4023 5.777294
109.1927 135.6685 5.776981
109.4593 135.9367 5.776984
109.7260 136.1994 5.776575
109.9960 136.4689 5.776176
110.2660 136.7405 5.775820
110.5362 137.0102 5.775440
110.8045 137.2835 5.775134
111.0760 137.5550 5.774960
111.3460 137.8208 5.774574
111.6160 138.0896 5.774129
111.8843 138.3606 5.773955
112.1526 138.6289 5.773628
112.4243 138.8956 5.773371
112.6918 139.1633 5.773203
112.9612 139.4298 5.772898
113.2327 139.7029 5.772520
113.4993 139.9710 5.771949
113.7693 140.2399 5.771695
114.0395 140.4524 5.771568
114.3095 140.6620 5.771280
114.5795 140.9140 5.770725
114.8493 141.1907 5.770452
115.1177 141.4814 5.770270
115.3860 141.7753 5.770153
115.6525 142.0695 5.769839
115.9192 142.3575 5.769270
116.1858 142.6398 5.768780
116.4528 142.9182 5.768470
116.7193 143.1906 5.768215
116.9860 143.4607 5.767812
117.2525 143.7293 5.767688
117.5193 143.9924 5.767245
117.7860 144.2566 5.767000
118.0526 144.5230 5.766608
118.3208 144.7944 5.766178
118.5903 145.0632 5.765836
118.8593 145.3321 5.765628
119.1310 145.6048 5.765125
119.3992 145.8725 5.764873
119.6677 146.1396 5.764414
119.9377 146.4098 5.763965
120.2077 146.6781 5.763600
120.4762 146.9466 5.763300
120.7443 147.2140 5.762902
121.0160 147.4860 5.762550
121.2834 147.7564 5.762666
121.5526 148.0241 5.762049
121.8243 148.2949 5.761682
122.0925 148.5632 5.761258
122.3643 148.8380 5.760754
122.6325 149.1032 5.760310
122.9010 149.3726 5.759930
123.1693 149.6412 5.759707
123.4362 149.9048 5.759473
123.7026 150.1699 5.759170
123.9693 150.4346 5.758756
124.2360 150.7022 5.758234
124.5025 150.9716 5.757584
124.7693 151.2391 5.757271
125.0360 151.5077 5.756806
125.3026 151.7750 5.756530
125.5692 152.0414 5.756161
125.8362 152.3087 5.755899
126.1027 152.5746 5.755528
126.3743 152.8462 5.755104
126.6412 153.1131 5.754782
126.9110 153.3841 5.754154
127.1808 153.6542 5.753660
127.4495 153.9208 5.753074
127.7193 154.1914 5.752850
127.9893 154.4590 5.752259
128.2560 154.7267 5.751660
128.5225 154.9943 5.751146
128.7895 155.2622 5.750725
129.0560 155.5275 5.750068
129.3226 155.7951 5.749620
129.5892 156.0616 5.749000
129.8562 156.3260 5.748513
130.1227 156.5932 5.747982
130.3893 156.8610 5.747482
130.6558 157.1277 5.747065
130.9245 157.3963 5.746485
131.1927 157.6669 5.746222
131.4644 157.9382 5.745488
131.7335 158.2076 5.744799
132.0008 158.4751 5.744039
132.2678 158.7407 5.743264
132.5343 159.0079 5.742750
132.8010 159.2745 5.742199
133.0678 159.5403 5.741546
133.3345 159.8073 5.740980
133.6012 160.0737 5.740209
133.8677 160.3394 5.739254
134.1344 160.6077 5.738526
134.4012 160.8734 5.737627
134.6693 161.1434 5.737046
134.9402 161.4140 5.736324
135.2092 161.6822 5.735484
135.4778 161.9498 5.734726
135.7460 162.2178 5.734011
136.0160 162.4861 5.733100
136.2825 162.7532 5.732207
136.5493 163.0210 5.731361
136.8158 163.2881 5.730354
137.0828 163.5534 5.729438
137.3494 163.8211 5.728464
137.6160 164.0863 5.727344
137.8827 164.3538 5.726292
138.1494 164.6225 5.725290
138.4162 164.8882 5.724320
138.6828 165.1572 5.723188
138.9495 165.4229 5.722002
139.2194 165.6916 5.720837
139.4902 165.9620 5.719538
139.7594 166.2307 5.718357
140.0310 166.5040 5.717049
140.2993 166.7726 5.715728
140.5677 167.0418 5.714253
140.8376 167.3121 5.712780
141.1078 167.5839 5.711193
141.3778 167.8559 5.709614
141.6460 168.1222 5.707963
141.9162 168.3926 5.706344
142.1853 168.6588 5.704520
142.4542 168.9247 5.702612
142.7245 169.1930 5.700634
142.9928 169.4629 5.698574
143.2645 169.7366 5.696528
143.5316 170.0034 5.694300
143.8012 170.2716 5.692071
144.0712 170.5411 5.689566
144.3412 170.8130 5.687201
144.6112 171.0835 5.684676
144.8812 171.3545 5.681963
145.1494 171.6263 5.679242
145.4193 171.8963 5.676382
145.6894 172.1672 5.673380
145.9594 172.4352 5.670215
146.2285 172.7028 5.667110
146.4993 172.9750 5.663700
146.7660 173.2414 5.660472
147.0327 173.5065 5.656932
147.2992 173.7709 5.653608
147.5662 174.0363 5.650100
147.8327 174.3034 5.646502
148.0995 174.5725 5.643000
148.3660 174.8410 5.639312
148.6327 175.1104 5.635712
148.8994 175.3766 5.632096
149.1660 175.6429 5.628564
149.4327 175.9076 5.624844
149.6994 176.1736 5.621042
149.9694 176.4387 5.616992
150.2394 176.7085 5.612945
150.5094 176.9812 5.609410
150.7793 177.2517 5.605637
151.0493 177.5250 5.601606
151.3177 177.7955 5.597690
151.5845 178.0619 5.593809
151.8512 178.3313 5.590176
152.1177 178.5964 5.586283
152.3844 178.8606 5.582432
152.6510 179.1251 5.578425
152.9178 179.3876 5.574387
153.1845 179.6583 5.570608
153.4510 179.9281 5.566921
153.7177 180.1905 5.563258
153.9845 180.4608 5.559312
154.2510 180.7303 5.555445
154.5177 180.9964 5.551486
154.7862 181.2656 5.547746
155.0577 181.5377 5.543701
155.3260 181.8029 5.539920
155.5927 182.0702 5.536116
155.8592 182.3349 5.532414
156.1262 182.6001 5.528662
156.3928 182.8664 5.524880
156.6593 183.1353 5.521140
156.9260 183.4014 5.517452
157.1927 183.6651 5.513786
157.4592 183.9319 5.510115
157.7262 184.2020 5.506363
157.9925 184.4660 5.502542
158.2594 184.7370 5.499004
158.5278 185.0033 5.495196
158.7942 185.2638 5.491574
159.0610 185.5296 5.487995
159.3276 185.8032 5.484286
159.5944 186.0712 5.480515
159.8610 186.3370 5.477184
160.1277 186.6019 5.473600
160.3944 186.8683 5.470031
160.6610 187.1332 5.466538
160.9277 187.3992 5.463166
161.1944 187.6668 5.459584
161.4610 187.9322 5.456250
161.7276 188.1999 5.452759
161.9944 188.4679 5.449285
162.2610 188.7364 5.445838
162.5276 189.0036 5.442608
162.7943 189.2702 5.439343
163.0610 189.5360 5.435742
163.3276 189.8026 5.432624
163.5944 190.0653 5.429200
163.8610 190.3302 5.425962
164.1277 190.5974 5.422750
164.3944 190.8641 5.419506
164.6627 191.1362 5.416495
164.9294 191.4034 5.413016
165.1960 191.6738 5.410088
165.4628 191.9390 5.406887
165.7295 192.2003 5.403736
165.9958 192.4652 5.400557
166.2627 192.7326 5.397421
166.5292 193.0002 5.394337
166.7962 193.2662 5.391404
167.0628 193.5343 5.388272
167.3294 193.8012 5.385315
167.5960 194.0676 5.382130
167.8660 194.3386 5.379044
168.1344 194.6064 5.376152
168.4008 194.8741 5.372961
168.6676 195.1426 5.370025
168.9344 195.4110 5.367250
169.2012 195.6748 5.364394
169.4678 195.9378 5.361638
169.7345 196.2045 5.358656
170.0012 196.4715 5.355778
170.2678 196.7412 5.353000
170.5345 197.0088 5.350281
170.8012 197.2760 5.347810
171.0678 197.5408 5.345100
171.3353 197.8089 5.342524
171.6026 198.0734 5.339528
171.8694 198.3438 5.336806
172.1360 198.6105 5.334290
172.4026 199.0001 5.325800
172.6695 199.2159 5.323637
172.9362 199.4361 5.320900
173.2028 199.6714 5.317606
173.4692 199.9191 5.314789
173.7360 200.1810 5.312896
174.0025 200.3690 5.312039
174.2692 200.6048 5.313540
174.5377 200.9386 5.311295
174.8076 201.2609 5.308930
175.0762 201.5609 5.306617
175.3445 201.8430 5.304510
175.6145 202.1167 5.302197
175.8835 202.3847 5.300151
176.1526 202.6468 5.297947
176.4244 202.9126 5.296050
176.6910 203.1719 5.294052
176.9610 203.4372 5.291822
177.2310 203.7066 5.289729
177.4995 203.9755 5.288123
177.7695 204.2462 5.285950
178.0378 204.5128 5.284414
178.3095 204.7823 5.282140
178.5785 205.0514 5.280580
178.8494 205.3205 5.278806
179.1176 205.5876 5.276890
179.3860 205.8563 5.275064
179.6562 206.1288 5.273284
179.9252 206.3980 5.271855
180.1925 206.6674 5.270274
180.4595 206.9344 5.268546
180.7260 207.1983 5.266943
180.9926 207.4650 5.265498
181.2595 207.7338 5.264033
181.5262 207.9997 5.262776
181.7926 208.2684 5.261262
182.0594 208.5320 5.259782
182.3262 208.7999 5.258601
182.5928 209.0651 5.257208
182.8594 209.3301 5.255893
183.1260 209.5964 5.254440
183.3945 209.8679 5.253418
183.6642 210.1357 5.252240
183.9312 210.4023 5.251125
184.1978 210.6695 5.250021
184.4642 210.9361 5.248598
184.7310 211.2032 5.247600
184.9977 211.4690 5.246598
185.2644 211.7380 5.245977
185.5310 212.0044 5.244954
185.7977 212.2718 5.243799
186.0644 212.5384 5.242753
186.3310 212.8022 5.242076
186.5994 213.0708 5.241213
186.8676 213.3406 5.240074
187.1360 213.6057 5.239679
187.4076 213.8773 5.238400
187.6752 214.1468 5.237912
187.9444 214.4177 5.236956
188.2110 214.6837 5.236292
188.4775 214.9525 5.235792
188.7445 215.2160 5.234948
189.0112 215.4831 5.234458
189.2775 215.7494 5.233330
189.5443 216.0160 5.233066
189.8110 216.2828 5.232191
190.0776 216.5520 5.231684
190.3444 216.8171 5.231026
190.6110 217.0840 5.230826
190.8777 217.3498 5.230024
191.1476 217.6201 5.229430
191.4160 217.8869 5.228640
191.6845 218.1567 5.228422
191.9542 218.4267 5.227817
192.2252 218.6956 5.227127
192.4926 218.9647 5.226918
192.7627 219.2350 5.226582
193.0326 219.5045 5.226060
193.3012 219.7694 5.225250
193.5700 220.0436 5.225244
193.8410 220.3127 5.224551
194.1094 220.5814 5.224429
194.3777 220.8484 5.223722
194.6495 221.1214 5.223540
194.9158 221.3897 5.223288
195.1825 221.6560 5.222504
195.4492 221.9239 5.222384
195.7162 222.1876 5.222211
195.9828 222.4546 5.221778
196.2495 222.7214 5.221296
196.5162 222.9856 5.220972
196.7828 223.2541 5.220847
197.0494 223.5216 5.220469
197.3160 223.7866 5.220050
197.5826 224.0559 5.219961
197.8510 224.3248 5.219732
198.1210 224.5918 5.219338
198.3910 224.8643 5.219072
198.6576 225.1315 5.218720
198.9242 225.3973 5.218668
199.1910 225.6639 5.218194
199.4576 225.9326 5.217790
199.7244 226.2016 5.217966
199.9912 226.4655 5.217332
200.2576 226.7306 5.216959
200.5244 226.9972 5.216820
200.7912 227.2642 5.216607
201.0576 227.5296 5.216199
201.3245 227.7970 5.216246
201.5926 228.0670 5.216125
201.8594 228.3328 5.215626
202.1260 228.6008 5.215472
202.3928 228.8648 5.215375
202.6594 229.1346 5.214904
202.9260 229.3994 5.215017
203.1927 229.6658 5.214511
203.4594 229.9347 5.214664
203.7258 230.1990 5.214022
203.9926 230.4661 5.214016
204.2592 230.7308 5.213757
204.5293 231.0006 5.213578
204.7992 231.2705 5.213228
205.0677 231.5396 5.213128
205.3362 231.8096 5.213011
205.6076 232.0824 5.212858
205.8754 232.3463 5.212566
206.1442 232.6152 5.212307
206.4160 232.8864 5.212148
206.6828 233.1538 5.212300
206.9526 233.4228 5.212038
207.2220 233.6944 5.211834
207.4910 233.9616 5.211626
207.7612 234.2304 5.211042
208.0293 234.5012 5.211346
208.2992 234.7708 5.211226
208.5685 235.0398 5.210621
208.8377 235.3111 5.210619
209.1045 235.5770 5.210256
209.3710 235.8424 5.210196
209.6375 236.1110 5.210332
209.9043 236.3747 5.209888
210.1708 236.6434 5.209835
210.4378 236.9098 5.209804
210.7043 237.1776 5.209954
210.9710 237.4442 5.209326
211.2378 237.7114 5.209624
211.5044 237.9761 5.209010
211.7710 238.2426 5.209213
212.0377 238.5102 5.208782
212.3092 238.7814 5.208796
212.5776 239.0496 5.208906
212.8494 239.3208 5.208506
213.1187 239.5922 5.208324
213.3894 239.8613 5.208066
213.6578 240.1313 5.208213
213.9260 240.3981 5.207854
214.1976 240.6689 5.207698
214.4666 240.9414 5.207752
214.7360 241.2088 5.207500
215.0076 241.4805 5.207320
215.2762 241.7482 5.207198
215.5444 242.0168 5.207174
215.8110 242.2832 5.206680
216.0776 242.5494 5.206646
216.3444 242.8148 5.206763
216.6112 243.0824 5.206513
216.8776 243.3472 5.206368
217.1444 243.6150 5.206117
217.4112 243.8820 5.205979
217.6777 244.1516 5.206042
217.9444 244.4158 5.206000
218.2128 244.6856 5.205821
218.4810 244.9542 5.205644
218.7510 245.2239 5.205766
219.0203 245.4928 5.205354
219.2910 245.7644 5.205430
219.5594 246.0313 5.205110
219.8278 246.3006 5.205158
220.0994 246.5707 5.204559
220.3668 246.8407 5.204612
220.6344 247.1080 5.204680
220.9012 247.3737 5.204496
221.1677 247.6423 5.204440
221.4344 247.9048 5.204136
221.7008 248.1750 5.203838
221.9678 248.4406 5.203938
222.2344 248.7076 5.203798
222.5010 248.9715 5.203606
222.7677 249.2382 5.203274
223.0342 249.5050 5.203400
223.3012 249.7700 5.203209
223.5675 250.0354 5.203082
223.8358 250.3098 5.203106
224.1078 250.5806 5.202868
224.3762 250.8480 5.202542
224.6458 251.1191 5.202783
224.9128 251.3840 5.202430
225.1795 251.6509 5.202341
225.4462 251.9190 5.202236
225.7127 252.1839 5.201854
225.9794 252.4543 5.202086
226.2458 252.7214 5.201772
226.5128 252.9870 5.201703
226.7792 253.2510 5.201720
227.0462 253.5174 5.201550
227.3125 253.7832 5.201498
227.5793 254.0498 5.201153
227.8494 254.3215 5.201104
228.1170 254.5892 5.200960
228.3860 254.8630 5.200978
228.6576 255.1331 5.200824
228.9244 255.3982 5.200856
229.1944 255.6649 5.200455
229.4637 255.9360 5.200564
229.7326 256.2049 5.200324
230.0026 256.4739 5.199944
230.2726 256.7476 5.200188
230.5410 257.0145 5.199938
230.8078 257.2800 5.199620
231.0743 257.5461 5.199558
231.3410 257.8140 5.199306
231.6076 258.0818 5.199459
231.8743 258.3477 5.199442
232.1408 258.6136 5.199123
232.4078 258.8782 5.199039
232.6745 259.1470 5.198705
232.9410 259.4140 5.198734
233.2076 259.6798 5.198622
233.4745 259.9460 5.198340
233.7426 260.2172 5.198498
234.0127 260.4857 5.198108
234.2826 260.7549 5.198200
234.5510 261.0234 5.197956
234.8194 261.2905 5.197896
235.0875 261.5604 5.197889
235.3544 261.8270 5.197561
235.6210 262.0930 5.197492
235.8877 262.3578 5.197324
236.1543 262.6294 5.197256
236.4210 262.8945 5.196924
236.6877 263.1630 5.196795
236.9543 263.4264 5.196760
237.2212 263.6919 5.196711
237.4878 263.9605 5.196346
237.7578 264.2292 5.196068
238.0260 264.4997 5.196088
238.2960 264.7680 5.195938
238.5660 265.0372 5.195732
238.8345 265.3071 5.195722
239.1044 265.5742 5.195728
239.3743 265.8448 5.195600
239.6410 266.1104 5.195230
239.9076 266.3774 5.195040
240.1742 266.6440 5.195160
240.4410 266.9118 5.194944
240.7078 267.1795 5.194702
240.9744 267.4448 5.194656
241.2408 267.7122 5.194369
241.5076 267.9782 5.194072
241.7745 268.2468 5.194065
242.0410 268.5110 5.194057
242.3076 268.7800 5.193996
242.5758 269.0502 5.193691
242.8477 269.3206 5.193445
243.1170 269.5886 5.193311
243.3860 269.8584 5.193352
243.6578 270.1298 5.192829
243.9260 270.3980 5.192716
244.1945 270.6633 5.192490
244.4642 270.9356 5.192690
244.7326 271.2042 5.192304
245.0026 271.4729 5.192234
245.2726 271.7478 5.192598
245.5425 272.0149 5.191968
245.8127 272.2864 5.191828
246.0828 272.5548 5.191868
246.3494 272.8215 5.191528
246.6160 273.0871 5.191552
246.8826 273.3523 5.191133
247.1494 273.6210 5.190790
247.4160 273.8888 5.191082
247.6826 274.1553 5.191116
247.9493 274.4238 5.191016
248.2158 274.6888 5.190485
248.4826 274.9559 5.190520
248.7493 275.2246 5.190522
249.0160 275.4906 5.190523
249.2844 275.7566 5.190281
249.5545 276.0238 5.189850
249.8210 276.2928 5.190012
250.0877 276.5569 5.189646
250.3544 276.8280 5.189990
250.6210 277.0946 5.189981
250.8877 277.3614 5.189615
251.1543 277.6268 5.189328
251.4212 277.8908 5.189070
251.6877 278.1580 5.189057
251.9543 278.4242 5.189202
252.2212 278.6916 5.188614
252.4875 278.9586 5.188863
252.7544 279.2246 5.188418
253.0244 279.4945 5.188354
253.2927 279.7633 5.188218
253.5618 280.0345 5.188389
253.8326 280.3053 5.188266
254.1010 280.5742 5.188176
254.3694 280.8438 5.187959
254.6408 281.1159 5.188022
254.9087 281.3830 5.187728
255.1777 281.6524 5.187731
255.4493 281.9232 5.187508
255.7160 282.1892 5.187430
255.9860 282.4580 5.187307
256.2526 282.7247 5.187036
256.5194 282.9936 5.187096
256.7860 283.2576 5.186728
257.0527 283.5239 5.186783
257.3192 283.7917 5.186526
257.5858 284.0596 5.186320
257.8525 284.3274 5.186470
258.1195 284.5930 5.186056
258.3860 284.8592 5.186213
258.6525 285.1257 5.186044
258.9194 285.3932 5.185696
259.1860 285.6572 5.185752
259.4560 285.9265 5.185570
259.7245 286.1950 5.185536
259.9944 286.4668 5.185489
260.2627 286.7349 5.185506
260.5295 287.0029 5.185306
260.7962 287.2712 5.185024
261.0626 287.5359 5.184920
261.3294 287.8016 5.184788
261.5960 288.0712 5.184696
261.8627 288.3334 5.184358
262.1292 288.6011 5.184272
262.3962 288.8676 5.184144
262.6626 289.1330 5.183930
262.9293 289.4012 5.183782
263.1960 289.6679 5.183769
263.4658 289.9388 5.183703
263.7345 290.2072 5.183510
264.0044 290.4760 5.183326
264.2745 290.7482 5.183038
264.5427 291.0168 5.183216
264.8110 291.2837 5.183000
265.0828 291.5541 5.182722
265.3504 291.8227 5.182900
265.6194 292.0927 5.182402
265.8910 292.3657 5.182524
266.1578 292.6308 5.182214
266.4244 292.8987 5.182194
266.6910 293.1662 5.182131
266.9578 293.4310 5.181926
267.2244 293.6962 5.181924
267.4910 293.9628 5.181776
267.7578 294.2305 5.181614
268.0243 294.4958 5.181602
268.2910 294.7613 5.181284
268.5576 295.0285 5.181339
268.8245 295.2952 5.181172
269.0944 295.5644 5.180814
269.3608 295.8322 5.180810
269.6276 296.1005 5.180878
269.8944 296.3684 5.180812
270.1610 296.6353 5.180984
270.4275 296.9016 5.180622
270.6944 297.1677 5.180416
270.9610 297.4334 5.180242
271.2276 297.7004 5.180094
271.4944 297.9672 5.180018
271.7612 298.2340 5.180008
272.0277 298.5018 5.179918
272.2945 298.7688 5.179867
272.5644 299.0368 5.179610
272.8345 299.3063 5.179309
273.1035 299.5754 5.179545
273.3728 299.8467 5.179406
273.6427 300.1134 5.179196
273.9112 300.3833 5.178913
274.1826 300.6564 5.178948
274.4504 300.9232 5.178726
274.7176 301.1934 5.178852
274.9844 301.4570 5.178575
275.2510 301.7244 5.178464
275.5177 301.9900 5.178325
275.7842 302.2568 5.178384
276.0510 302.5254 5.178118
276.3178 302.7900 5.178066
276.5844 303.0585 5.177844
276.8512 303.3228 5.177722
277.1177 303.5919 5.177786
277.3845 303.8569 5.177527
277.6527 304.1246 5.177344
277.9195 304.3905 5.177124
278.1860 304.6581 5.176938
278.4528 304.9251 5.176968
278.7194 305.1900 5.176826
278.9862 305.4592 5.176860
279.2526 305.7250 5.176793
279.5192 305.9924 5.176684
279.7860 306.2580 5.176419
280.0527 306.5242 5.176438
280.3195 306.7910 5.176203
280.5894 307.0636 5.176338
280.8587 307.3332 5.176121
281.1276 307.6018 5.175965
281.3992 307.8713 5.176020
281.6660 308.1374 5.175706
281.9360 308.4083 5.175578
282.2041 308.6784 5.175703
282.4710 308.9447 5.175317
282.7375 309.2125 5.175506
283.0045 309.4784 5.175234
283.2710 309.7429 5.174985
283.5378 310.0089 5.174879
283.8043 310.2790 5.175051
284.0708 310.5438 5.174716
284.3378 310.8102 5.174621
284.6044 311.0769 5.174370
284.8711 311.3452 5.174340
285.1394 311.6131 5.174114
285.4083 311.8778 5.174016
285.6777 312.1486 5.173750
285.9495 312.4262 5.174014
286.2176 312.6898 5.173681
286.4878 312.9589 5.173680
286.7576 313.2297 5.173507
287.0245 313.4966 5.173433
287.2910 313.7620 5.173364
287.5578 314.0303 5.173252
287.8244 314.2959 5.172869
288.0910 314.5621 5.172820
288.3578 314.8276 5.172737
288.6243 315.0951 5.172707
288.8908 315.3627 5.172422
289.1576 315.6312 5.172470
289.4244 315.8961 5.172246
289.6910 316.1625 5.172283
289.9604 316.4326 5.172066
290.2295 316.7005 5.171900
290.4993 316.9712 5.171906
290.7677 317.2383 5.171803
291.0376 317.5089 5.171648
291.3085 317.7820 5.171461
291.5760 318.0491 5.171412
291.8462 318.3197 5.171416
292.1162 318.5910 5.171338
292.3845 318.8572 5.171085
292.6537 319.1262 5.171162
292.9244 319.3961 5.171062
293.1926 319.6646 5.170632
293.4610 319.9348 5.170517
293.7326 320.2046 5.170605
294.0018 320.4752 5.170603
294.2710 320.7438 5.170396
294.5410 321.0128 5.170154
294.8094 321.2810 5.170004
295.0810 321.5532 5.170211
295.3502 321.8230 5.170160
295.6195 322.0942 5.169996
295.8895 322.3630 5.170090
296.1575 322.6310 5.169685
296.4275 322.8995 5.169622
296.6960 323.1694 5.169571
296.9627 323.4350 5.169439
297.2294 323.7018 5.169420
297.4960 323.9682 5.169395
297.7627 324.2337 5.169228
298.0293 324.5296 5.166824
298.2960 324.8106 5.163194
298.5625 325.0625 5.162543
298.8294 325.3163 5.162815
299.0960 325.5725 5.163217
299.3627 325.8300 5.163010
299.6295 326.0954 5.162476
299.8977 326.3186 5.168306
300.1660 326.6018 5.168320
300.4344 326.8877 5.168183
300.7010 327.1670 5.168250
300.9678 327.4422 5.168063
301.2345 327.7126 5.167668
301.5012 327.9823 5.167652
301.7675 328.2482 5.167504
302.0344 328.5126 5.167300
302.3010 328.7760 5.167222
302.5676 329.0422 5.167217
302.8344 329.3110 5.167286
303.1010 329.5731 5.167270
303.3694 329.8428 5.166920
303.6410 330.1145 5.166656
303.9076 330.3813 5.166972
304.1777 330.6516 5.166386
304.4478 330.9197 5.166406
304.7142 331.1828 5.166368
304.9808 331.4542 5.166387
305.2477 331.7202 5.166153
305.5144 331.9890 5.166344
305.7810 332.2561 5.165924
306.0476 332.5208 5.165854
306.3144 332.7875 5.165710
306.5810 333.0537 5.165670
306.8476 333.3218 5.165709
307.1145 333.5869 5.165581
307.3812 333.8538 5.165515
307.6484 334.1214 5.165665
307.9160 334.3896 5.165445
308.1862 334.6582 5.165257
308.4541 334.9241 5.165046
308.7244 335.1976 5.164922
308.9935 335.4668 5.164888
309.2627 335.7380 5.164952
309.5293 336.0039 5.164796
309.7960 336.2730 5.164873
310.0625 336.5381 5.164883
310.3291 336.8009 5.164744
310.5962 337.0694 5.164731
310.8627 337.3382 5.164600
311.1294 337.6032 5.164371
311.3959 337.8714 5.164126
311.6628 338.1387 5.164226
311.9293 338.4039 5.164136
312.1960 338.6678 5.164084
312.4645 338.9372 5.164187
312.7326 339.2040 5.164184
312.9993 339.4730 5.163900
313.2658 339.7378 5.163533
313.5325 340.0055 5.163683
313.7995 340.2718 5.163654
314.0660 340.5410 5.163588
314.3326 340.8106 5.163699
314.5994 341.0715 5.163316
314.8658 341.3437 5.163504
315.1326 341.6062 5.163356
315.3993 341.8731 5.163278
315.6677 342.1411 5.163115
315.9395 342.4144 5.162766
316.2076 342.6833 5.162788
316.4760 342.9498 5.162866
316.7428 343.2184 5.162982
317.0094 343.4875 5.162674
317.2760 343.7510 5.162552
317.5427 344.0195 5.162778
317.8094 344.2837 5.162484
318.0758 344.5526 5.162410
318.3428 344.8174 5.162262
318.6094 345.0816 5.162340
318.8762 345.3488 5.162022
319.1427 345.6181 5.162086
319.4112 345.8860 5.161956
319.6810 346.1548 5.161878
319.9500 346.4223 5.161776
320.2176 346.6904 5.161804
320.4878 346.9595 5.161498
320.7576 347.2304 5.161684
321.0258 347.5000 5.161598
321.2952 347.7704 5.161450
321.5660 348.0398 5.161344
321.8345 348.3090 5.161308
322.1026 348.5761 5.161062
322.3743 348.8466 5.161022
322.6408 349.1072 5.160512
322.9076 349.3813 5.160858
323.1744 349.6496 5.160711
323.4412 349.9164 5.160430
323.7076 350.1806 5.160522
323.9744 350.4490 5.160442
324.2412 350.7135 5.160402
324.5076 350.9828 5.160162
324.7745 351.2497 5.160265
325.0410 351.5159 5.160236
325.3075 351.7796 5.159724
325.5745 352.0461 5.159906
325.8435 352.3156 5.159861
326.1127 352.5863 5.159697
326.3794 352.8525 5.159631
326.6460 353.1148 5.159380
326.9128 353.3878 5.159558
327.1793 353.6525 5.159625
327.4460 353.9156 5.159384
327.7126 354.1848 5.159362
327.9794 354.4506 5.159046
328.2458 354.7191 5.159358
328.5128 354.9861 5.159042
328.7792 355.2528 5.159234
329.0462 355.5158 5.159131
329.3145 355.7908 5.158563
329.5844 356.0587 5.158869
329.8526 356.3269 5.158811
330.1210 356.5918 5.158721
330.3875 356.8614 5.158400
330.6545 357.1281 5.158550
330.9210 357.3956 5.158312
331.1876 357.6620 5.158485
331.4544 357.9284 5.158354
331.7212 358.1922 5.158312
331.9876 358.4619 5.158128
332.2544 358.7297 5.158194
332.5210 358.9937 5.157985
332.7878 359.2641 5.158037
333.0545 359.5272 5.157687
333.3244 359.7998 5.157728
333.5935 360.0676 5.157588
333.8628 360.3384 5.157629
334.1326 360.6076 5.157589
334.4010 360.8760 5.157660
334.6710 361.1433 5.157389
334.9376 361.4114 5.157462
335.2045 361.6785 5.157350
335.4710 361.9456 5.157265
335.7376 362.2121 5.157141
336.0042 362.4794 5.157043
336.2710 362.7456 5.156954
336.5376 363.0125 5.156908
336.8045 363.2784 5.156946
337.0710 363.5454 5.156980
337.3376 363.8116 5.156838
337.6045 364.0782 5.156694
337.8727 364.3492 5.156530
338.1410 364.6156 5.156450
338.4075 364.8778 5.156524
338.6744 365.1492 5.156514
338.9410 365.4170 5.156396
339.2078 365.6860 5.156526
339.4744 365.9490 5.156128
339.7410 366.2178 5.156248
340.0078 366.4817 5.156011
340.2743 366.7490 5.155848
340.5410 367.0139 5.155784
340.8075 367.2820 5.155930
341.0744 367.5500 5.155842
341.3418 367.8152 5.155639
341.6112 368.0836 5.155259
341.8826 368.3613 5.155454
342.1493 368.6217 5.155084
342.4162 368.8886 5.155428
342.6826 369.1577 5.155468
342.9495 369.4218 5.155366
343.2160 369.6894 5.155144
343.4825 369.9559 5.155028
343.7493 370.2200 5.154734
344.0160 370.4900 5.154750
344.2826 370.7589 5.154861
344.5494 371.0234 5.154766
344.8158 371.2886 5.154438
345.0828 371.5572 5.154705
345.3510 371.8230 5.154283
345.6227 372.0962 5.154459
345.8910 372.3640 5.154380
346.1594 372.6309 5.153996
346.4295 372.9034 5.154174
346.6978 373.1703 5.154065
346.9676 373.4419 5.153776
347.2376 373.7139 5.153787
347.5076 373.9829 5.153962
347.7743 374.2490 5.153652
348.0412 374.5161 5.153690
348.3076 374.7835 5.153730
348.5744 375.0481 5.153446
348.8412 375.3142 5.153262
349.1076 375.5797 5.153332
349.3743 375.8494 5.153429
349.6410 376.1140 5.152859
349.9075 376.3818 5.153050
350.1742 376.6456 5.153000
350.4410 376.9135 5.152980
350.7075 377.1804 5.152597
350.9741 377.4484 5.152896
351.2410 377.7158 5.152691
351.5076 377.9792 5.152504
351.7743 378.2472 5.152437
352.0410 378.5134 5.152353
352.3076 378.7804 5.152451
352.5745 379.0462 5.152371
352.8408 379.3144 5.152282
353.1075 379.5818 5.152053
353.3743 379.8457 5.151910
353.6418 380.1164 5.152140
353.9110 380.3855 5.151778
354.1777 380.6526 5.151850
354.4444 380.9178 5.151788
354.7110 381.1840 5.151730
354.9776 381.4525 5.151566
355.2445 381.7182 5.151496
355.5112 381.9856 5.151559
355.7777 382.2499 5.151218
356.0444 382.5145 5.151253
356.3110 382.7840 5.151134
356.5776 383.0515 5.150929
356.8454 383.3187 5.150692
357.1159 383.5905 5.151020
357.3826 383.8572 5.150918
357.6493 384.1244 5.150803
357.9162 384.3890 5.150364
358.1826 384.6564 5.150556
358.4494 384.9242 5.150410
358.7160 385.1880 5.150082
358.9828 385.4540 5.150113
359.2493 385.7214 5.150272
359.5160 385.9876 5.150207
359.7828 386.2549 5.149858
360.0495 386.5225 5.150204
360.3176 386.7912 5.149840
360.5860 387.0584 5.149738
360.8526 387.3256 5.149746
361.1192 387.5933 5.149522
361.3859 387.8613 5.149416
361.6528 388.1279 5.149667
361.9194 388.3956 5.149380
362.1858 388.6637 5.149402
362.4526 388.9298 5.149411
362.7194 389.1950 5.149430
362.9859 389.4609 5.149209
363.2528 389.7257 5.148854
363.5210 389.9937 5.148944
363.7908 390.2636 5.148866
364.0594 390.5340 5.148866
364.3291 390.8042 5.148855
364.5994 391.0756 5.148798
364.8676 391.3434 5.149102
365.1395 391.6140 5.148730
365.4076 391.8820 5.148476
365.6778 392.1520 5.148756
365.9444 392.4200 5.148650
366.2112 392.6878 5.148621
366.4776 392.9532 5.148450
366.7444 393.2178 5.148268
367.0112 393.4875 5.148428
367.2775 393.7526 5.148312
367.5444 394.0214 5.148037
367.8110 394.2866 5.147969
368.0778 394.5515 5.147700
368.3444 394.8197 5.147822
368.6110 395.0870 5.147797
368.8828 395.3548 5.147754
369.1516 395.6240 5.147665
369.4210 395.8981 5.147527
369.6912 396.1656 5.147657
369.9576 396.4325 5.147515
370.2245 396.6989 5.147488
370.4910 396.9638 5.147167
370.7578 397.2301 5.147330
371.0243 397.4983 5.147098
371.2912 397.7642 5.146908
371.5576 398.0320 5.147026
371.8242 398.2971 5.147050
372.0910 398.5668 5.146906
372.3575 398.8290 5.146526
372.6243 399.0998 5.146742
372.8944 399.3712 5.146631
373.1628 399.6382 5.146542
373.4344 399.9087 5.146734
373.7037 400.1775 5.146597
373.9744 400.4480 5.146690
374.2444 400.7200 5.146694
374.5126 400.9872 5.146543
374.7844 401.2604 5.146588
375.0535 401.5290 5.146411
375.3245 401.8008 5.146502
375.5928 402.0687 5.146256
375.8612 402.3367 5.146056
376.1312 402.6050 5.146176
376.3992 402.8709 5.145979
376.6660 403.1414 5.146179
376.9325 403.4059 5.145972
377.1992 403.6731 5.146040
377.4660 403.9395 5.145730
377.7326 404.2058 5.145710
377.9993 404.4723 5.145774
378.2660 404.7410 5.145633
378.5326 405.0070 5.145734
378.7994 405.2752 5.145800
379.0660 405.5408 5.145600
379.3326 405.8080 5.145605
379.6018 406.0772 5.145503
379.8727 406.3460 5.145520
380.1426 406.6172 5.145464
380.4109 406.8909 5.145790
380.6826 407.1603 5.145483
380.9519 407.4303 5.145468
381.2226 407.6989 5.145250
381.4909 407.9676 5.145033
381.7594 408.2365 5.145054
382.0310 408.5056 5.144974
382.2994 408.7742 5.145008
382.5676 409.0417 5.144875
382.8394 409.3150 5.144974
383.1076 409.5814 5.144674
383.3776 409.8543 5.144890
383.6485 410.1222 5.144668
383.9158 410.3909 5.144712
384.1862 410.6582 5.144516
384.4560 410.9300 5.144602
384.7260 411.1991 5.144575
384.9944 411.4678 5.144459
385.2610 411.7379 5.144384
385.5277 412.0045 5.144486
385.7945 412.2697 5.144280
386.0610 412.5357 5.144373
386.3276 412.8030 5.144358
386.5945 413.0688 5.144236
386.8612 413.3329 5.144107
387.1276 413.6016 5.144098
387.3944 413.8670 5.144056
387.6610 414.1334 5.143916
387.9292 414.4048 5.143814
388.1976 414.6738 5.143910
388.4662 414.9377 5.143788
388.7362 415.2076 5.143932
389.0060 415.4774 5.143801
389.2760 415.7494 5.143670
389.5453 416.0162 5.143543
389.8160 416.2867 5.143575
390.0844 416.5531 5.143310
390.3526 416.8276 5.143554
390.6194 417.0942 5.143330
390.8862 417.3602 5.143408
391.1527 417.6274 5.143214
391.4195 417.8956 5.143375
391.6860 418.1591 5.143156
391.9525 418.4285 5.143254
392.2195 418.6955 5.143084
392.4860 418.9598 5.143000
392.7526 419.2248 5.142934
393.0194 419.4932 5.142924
393.2860 419.7624 5.142837
393.5544 420.0290 5.142735
393.8244 420.2978 5.142613
394.0918 420.5668 5.142628
394.3609 420.8370 5.142534
394.6325 421.1076 5.142338
394.8993 421.3740 5.142624
395.1660 421.6412 5.142380
395.4325 421.9094 5.142292
395.6994 422.1713 5.142260
395.9660 422.4367 5.142306
396.2326 422.7036 5.142229
396.4993 422.9739 5.142048
396.7660 423.2403 5.141957
397.0328 423.5074 5.141991
397.2994 423.7754 5.142039
397.5662 424.0422 5.141852
397.8325 424.3072 5.141726
398.0994 424.5738 5.141810
398.3344 424.8110 5.141648